<?xml version="1.0"?>
<robot xmlns:xacro="http://www.ros.org/wiki/xacro" name="custom_robot">

    <link name="dummy">
   </link>

    <link name="base_assembly">
        <visual>
            <origin
                xyz="7.6327832942979512154e-17 -4.8572257327350598644e-17 1.561251128379126385e-17"
                rpy="-5.7607944447429549523e-31 -5.6155525133382567877e-30 1.570796326794896558" />
            <geometry>
                <mesh filename="package://custom_robot_description/meshes/base_middle.stl" />
            </geometry>
            <material name="base_middle_material">
                <color
                    rgba="0.26274509803921569651 0.28235294117647058432 0.30196078431372547213 1.0" />
            </material>
        </visual>
        <collision>
            <origin
                xyz="7.6327832942979512154e-17 -4.8572257327350598644e-17 1.561251128379126385e-17"
                rpy="-5.7607944447429549523e-31 -5.6155525133382567877e-30 1.570796326794896558" />
            <geometry>
                <mesh filename="package://custom_robot_description/meshes/base_middle.stl" />
            </geometry>
        </collision>
        <visual>
            <origin
                xyz="1.8928488461570885284e-18 4.320400756200346338e-18 0.0074999999999999997224"
                rpy="-3.141592653589793116 2.9063838698217552199e-30 -1.570796326794896558" />
            <geometry>
                <mesh filename="package://custom_robot_description/meshes/base_lower.stl" />
            </geometry>
            <material name="base_lower_material">
                <color
                    rgba="0.26274509803921569651 0.28235294117647058432 0.30196078431372547213 1.0" />
            </material>
        </visual>
        <collision>
            <origin
                xyz="1.8928488461570885284e-18 4.320400756200346338e-18 0.0074999999999999997224"
                rpy="-3.141592653589793116 2.9063838698217552199e-30 -1.570796326794896558" />
            <geometry>
                <mesh filename="package://custom_robot_description/meshes/base_lower.stl" />
            </geometry>
        </collision>

        <visual>
            <origin xyz="6.9388939039072283776e-17 -5.1824863844807111946e-17 0"
                rpy="1.6653345369377343176e-16 -1.1033889800371262025e-29 1.570796326794896558" />
            <geometry>
                <mesh filename="package://custom_robot_description/meshes/base_top.stl" />
            </geometry>
            <material name="base_top_material">
                <color
                    rgba="0.26274509803921569651 0.28235294117647058432 0.30196078431372547213 1.0" />
            </material>
        </visual>
        <collision>
            <origin xyz="6.9388939039072283776e-17 -5.1824863844807111946e-17 0"
                rpy="1.6653345369377343176e-16 -1.1033889800371262025e-29 1.570796326794896558" />
            <geometry>
                <mesh filename="package://custom_robot_description/meshes/base_top.stl" />
            </geometry>
        </collision>

        <inertial>
            <origin xyz="-0.001542595617879283015 7.4859604726511863094e-05 0.076585386411099687365"
                rpy="0 0 0" />
            <mass value="1.2131521714515483001" />
            <inertia ixx="0.0023760588998421702973" ixy="-5.7213472223065316455e-07"
                ixz="-1.9860393470310413718e-05" iyy="0.0022290834357577638328"
                iyz="-1.035950274458222666e-07" izz="0.0013727513678298568136" />
        </inertial>
    </link>


    <link name="base_link_assembly">
        <visual>
            <origin
                xyz="6.4958129518298437265e-14 -5.1940259741244153244e-15 0.14450000000000001732"
                rpy="-3.141592653589793116 1.5533833520453285648e-30 9.2033763872809041003e-46" />
            <geometry>
                <mesh filename="package://custom_robot_description/meshes/base_link_right.stl" />
            </geometry>
            <material name="base_link_right_material">
                <color rgba="1 0.30980392156862746056 0.031372549019607842702 1.0" />
            </material>
        </visual>
        <collision>
            <origin
                xyz="6.4958129518298437265e-14 -5.1940259741244153244e-15 0.14450000000000001732"
                rpy="-3.141592653589793116 1.5533833520453285648e-30 9.2033763872809041003e-46" />
            <geometry>
                <mesh filename="package://custom_robot_description/meshes/base_link_right.stl" />
            </geometry>
        </collision>
        <visual>
            <origin
                xyz="6.4988652909861072635e-14 -5.2062804373423747299e-15 0.14450000000000001732"
                rpy="3.141592653589793116 3.1344489146208747676e-34 1.5833879800483534083e-47" />
            <geometry>
                <mesh filename="package://custom_robot_description/meshes/base_link.stl" />
            </geometry>
            <material name="base_link_material">
                <color rgba="1 0.30980392156862746056 0.031372549019607842702 1.0" />
            </material>
        </visual>
        <collision>
            <origin
                xyz="6.4988652909861072635e-14 -5.2062804373423747299e-15 0.14450000000000001732"
                rpy="3.141592653589793116 3.1344489146208747676e-34 1.5833879800483534083e-47" />
            <geometry>
                <mesh filename="package://custom_robot_description/meshes/base_link.stl" />
            </geometry>
        </collision>

        <visual>
            <origin
                xyz="6.5024049010385568556e-14 -5.1940259741244153244e-15 0.14450000000000001732"
                rpy="-3.141592653589793116 2.3668961605544966388e-30 1.2199293674259672683e-45" />
            <geometry>
                <mesh filename="package://custom_robot_description/meshes/base_link_left.stl" />
            </geometry>
            <material name="base_link_left_material">
                <color rgba="1 0.30980392156862746056 0.031372549019607842702 1.0" />
            </material>
        </visual>
        <collision>
            <origin
                xyz="6.5024049010385568556e-14 -5.1940259741244153244e-15 0.14450000000000001732"
                rpy="-3.141592653589793116 2.3668961605544966388e-30 1.2199293674259672683e-45" />
            <geometry>
                <mesh filename="package://custom_robot_description/meshes/base_link_left.stl" />
            </geometry>
        </collision>
        <visual>
            <origin
                xyz="6.4952925347870506843e-14 -5.2079037619322297811e-15 0.14450000000000001732"
                rpy="-3.141592653589793116 2.3668961605544966388e-30 1.2418246559310425351e-45" />
            <geometry>
                <mesh filename="package://custom_robot_description/meshes/base_link_right_adjust.stl" />
            </geometry>
            <material name="base_link_right_adjust_material">
                <color rgba="1 0.30980392156862746056 0.031372549019607842702 1.0" />
            </material>
        </visual>
        <collision>
            <origin
                xyz="6.4952925347870506843e-14 -5.2079037619322297811e-15 0.14450000000000001732"
                rpy="-3.141592653589793116 2.3668961605544966388e-30 1.2418246559310425351e-45" />
            <geometry>
                <mesh filename="package://custom_robot_description/meshes/base_link_right_adjust.stl" />
            </geometry>
        </collision>
        <inertial>
            <origin
                xyz="0.00082361805441200010725 -0.011115725133235903124 -0.017306790465385243211"
                rpy="0 0 0" />
            <mass value="0.32250812130220907203" />
            <inertia ixx="0.00036639134951843061903" ixy="7.7021739428057928723e-07"
                ixz="-2.0290187882690739296e-06" iyy="0.00077354348158384465123"
                iyz="-8.8493966946928540648e-05" izz="0.00088328503025208017583" />
        </inertial>
    </link>

    <link name="long_arm_assembly">
        <visual>
            <origin xyz="1.3877787807814456755e-17 0 0.079500000000000015099"
                rpy="-3.141592653589793116 -2.7755575615628919674e-17 -1.4273933150031458811e-17" />
            <geometry>
                <mesh filename="package://custom_robot_description/meshes/long_arm_middle.stl" />
            </geometry>
            <material name="long_arm_middle_material">
                <color rgba="1 0.30980392156862746056 0.031372549019607842702 1.0" />
            </material>
        </visual>
        <collision>
            <origin xyz="1.3877787807814456755e-17 0 0.079500000000000015099"
                rpy="-3.141592653589793116 -2.7755575615628919674e-17 -1.4273933150031458811e-17" />
            <geometry>
                <mesh filename="package://custom_robot_description/meshes/long_arm_middle.stl" />
            </geometry>
        </collision>
        <visual>
            <origin xyz="0 0 0.079500000000000015099"
                rpy="3.141592653589793116 -8.1417180508639702179e-34 0" />
            <geometry>
                <mesh filename="package://custom_robot_description/meshes/long_arm_base.stl" />
            </geometry>
            <material name="long_arm_base_material">
                <color rgba="1 0.30980392156862746056 0.031372549019607842702 1.0" />
            </material>
        </visual>
        <collision>
            <origin xyz="0 0 0.079500000000000015099"
                rpy="3.141592653589793116 -8.1417180508639702179e-34 0" />
            <geometry>
                <mesh filename="package://custom_robot_description/meshes/long_arm_base.stl" />
            </geometry>
        </collision>
        <visual>
            <origin xyz="6.9388939039072283776e-18 0 0.079500000000000015099"
                rpy="-3.141592653589793116 -2.7755575615628904266e-17 2.696328493119530383e-17" />
            <geometry>
                <mesh filename="package://custom_robot_description/meshes/long_arm_top.stl" />
            </geometry>
            <material name="long_arm_top_material">
                <color rgba="1 0.30980392156862746056 0.031372549019607842702 1.0" />
            </material>
        </visual>
        <collision>
            <origin xyz="6.9388939039072283776e-18 0 0.079500000000000015099"
                rpy="-3.141592653589793116 -2.7755575615628904266e-17 2.696328493119530383e-17" />
            <geometry>
                <mesh filename="package://custom_robot_description/meshes/long_arm_top.stl" />
            </geometry>
        </collision>
        <inertial>
            <origin xyz="0.028569336974038909288 -2.0970815339696197431e-05 0.044400066767273795032"
                rpy="0 0 0" />
            <mass value="0.90360932281943473487" />
            <inertia ixx="0.00054965729563856229566" ixy="-3.3812220666681987968e-07"
                ixz="0.00037351385811721320553" iyy="0.0031534497991927415081"
                iyz="-7.3787465634249822647e-07" izz="0.0030252569355456821951" />
        </inertial>
    </link>

    <link name="assembly_top_link_dc">
        <visual>
            <origin xyz="-0.024000000000000853984 -0.027499999999999386047 0.021500000000000605432"
                rpy="-1.4565394515262064111e-14 -7.7101989535350279367e-32 -1.1676325758691105984e-30" />
            <geometry>
                <mesh filename="package://custom_robot_description/meshes/dc_link_base.stl" />
            </geometry>
            <material name="dc_link_base_material">
                <color rgba="1 0.30980392156862746056 0.031372549019607842702 1.0" />
            </material>
        </visual>
        <collision>
            <origin xyz="-0.024000000000000853984 -0.027499999999999386047 0.021500000000000605432"
                rpy="-1.4565394515262064111e-14 -7.7101989535350279367e-32 -1.1676325758691105984e-30" />
            <geometry>
                <mesh filename="package://custom_robot_description/meshes/dc_link_base.stl" />
            </geometry>
        </collision>


        <visual>
            <origin xyz="-0.024000000000001103784 -0.027499999999999691358 0.021500000000000445838"
                rpy="-1.456539451526209251e-14 -8.9232629009785703484e-32 -1.9267878350028823092e-30" />
            <geometry>
                <mesh filename="package://custom_robot_description/meshes/dc_link_top.stl" />
            </geometry>
            <material name="dc_link_top_material">
                <color rgba="1 0.30980392156862746056 0.031372549019607842702 1.0" />
            </material>
        </visual>
        <collision>
            <origin xyz="-0.024000000000001103784 -0.027499999999999691358 0.021500000000000445838"
                rpy="-1.456539451526209251e-14 -8.9232629009785703484e-32 -1.9267878350028823092e-30" />
            <geometry>
                <mesh filename="package://custom_robot_description/meshes/dc_link_top.stl" />
            </geometry>
        </collision>
        <visual>
            <origin xyz="-0.024000000000000965006 -0.027499999999999691358 0.021500000000000334816"
                rpy="-1.5092750451958890405e-14 -8.9232629009785703484e-32 -1.9267878350028823092e-30" />
            <geometry>
                <mesh filename="package://custom_robot_description/meshes/dc_link_cover.stl" />
            </geometry>
            <material name="dc_link_cover_material">
                <color rgba="1 0.30980392156862746056 0.031372549019607842702 1.0" />
            </material>
        </visual>
        <collision>
            <origin xyz="-0.024000000000000965006 -0.027499999999999691358 0.021500000000000334816"
                rpy="-1.5092750451958890405e-14 -8.9232629009785703484e-32 -1.9267878350028823092e-30" />
            <geometry>
                <mesh filename="package://custom_robot_description/meshes/dc_link_cover.stl" />
            </geometry>
        </collision>
        <inertial>
            <origin xyz="0.037698637107383164979 -0.00043549984585142156434 0.038060760383678608754"
                rpy="0 0 0" />
            <mass value="0.58783652981254619352" />
            <inertia ixx="0.00016298449244906711673" ixy="2.1834775486479800067e-06"
                ixz="6.0817628740002035331e-05" iyy="0.0012902902698479349394"
                iyz="5.4432553906056626553e-07" izz="0.0013143562983533394611" />
        </inertial>
    </link>


    <joint name="dummy_joint" type="fixed">
     <parent link="dummy"/>
     <child link="base_assembly"/>
   </joint>


    <joint name="joint_1" type="revolute">
        <origin xyz="8.2399358337663425366e-18 -1.45283058656038292e-17 0.14549999999999982392"
            rpy="3.1415926535897926719 2.2133878977684725821e-16 1.570796326794896558" />
        <parent link="base_assembly" />
        <child link="base_link_assembly" />
        <axis xyz="0 0 1" />
        <limit effort="1" velocity="20" lower="-3.141592653589793116" upper="3.141592653589793116" />
        <joint_properties friction="0.0" />
    </joint>

    <joint name="joint_2" type="revolute">
        <origin xyz="-0.050999999997120751272 -0.037145706961471312846 -0.040961940777125588342"
            rpy="-1.57079632679489678 1.4504177070403416247e-15 -1.570796326794896558" />
        <parent link="base_link_assembly" />
        <child link="long_arm_assembly" />
        <axis xyz="0 0 1" />
        <limit effort="1" velocity="20" lower="0" upper="3.141592653589793116" />
        <joint_properties friction="0.0" />
    </joint>

    <joint name="joint_3" type="revolute">
        <origin xyz="0.17400000000000004352 2.7755575615628913511e-17 0.027000000000000023981"
            rpy="-2.6681930982016667378e-16 3.5914084545178325344e-16 -1.570796326794896558" />
        <parent link="long_arm_assembly" />
        <child link="assembly_top_link_dc" />
        <axis xyz="0 0 1" />
        <limit effort="1" velocity="20" lower="-0.785398163397448279" upper="3.141592653589793116" />
        <joint_properties friction="0.0" />
    </joint>


</robot>